<mujoco model="soccer_kick_demo">
  <compiler inertiafromgeom="true" angle="degree"/>
  <option timestep="0.002" gravity="0 0 -9.81"/>

  <worldbody>
    <!-- Ground -->
    <geom name="ground" type="plane" size="12 12 0.1" rgba="0.25 0.32 0.25 1"
        friction="1.5 0.01 0.01" condim="3" solimp="0.95 0.99 0.001" solref="0.002 1"/>

    <!-- Goal frame at x=5 (white posts are collidable) -->
    <body name="goal" pos="5 0 0.9">
      <!-- posts (white) -->
      <geom name="left_post"  type="box" size="0.05 0.05 0.9" pos="0  1.2 0"
            rgba="1 1 1 1"/>
      <geom name="right_post" type="box" size="0.05 0.05 0.9" pos="0 -1.2 0"
            rgba="1 1 1 1"/>
      <geom name="crossbar"   type="box" size="0.05 1.2 0.05" pos="0 0 0.9"
            rgba="1 1 1 1"/>
      <!-- visual "net" plane (non-collidable) -->
      <geom name="net" type="box" size="0.02 1.2 0.9" pos="0 0 0"
            rgba="0.1 0.1 0.6 0.15" contype="0" conaffinity="0"/>
      <!-- target marker for RL (center of goal) -->
      <site name="target" pos="0 0 0" size="0.08" rgba="1 0 0 0.8"/>
    </body>

    <!-- Ball centered at y=0 -->
    <body name="ball" pos="-0.35 0 0.11">
        <joint name="ball_free" type="free" damping="0.002"/>
        <geom type="sphere" size="0.11" mass="0.20"
                rgba="0.85 0.85 0.85 1" friction="1.0 0.02 0.002" condim="3"/>
    </body>



    <!-- Kicker arm: swings horizontally toward +X -->
    <body name="kicker" pos="-1.0 -0.25 0.11">
        <!-- hinge around the Y-axis to swing forward in +X -->
        <joint name="hinge" type="hinge" axis="0 1 0" range="-35 35"/>
        <geom name="foot" type="capsule" fromto="0 0 0 0.3 0 0" size="0.03" rgba="1 0 0 1"/>
        <site name="kick_site" pos="0.3 0 0" size="0.02" rgba="1 0 0 1"/>
    </body>

  </worldbody>

  <actuator>
    <!-- torque motor on the hinge to "kick" -->
    <motor name="kick_motor" joint="hinge" ctrlrange="-1 1" gear="300"/>
  </actuator>
</mujoco>

